Workbook

Sheet Summary
A1: CxChanger build cost — Summary
A2: ="Tools: "&Assumptions!B4&" | Printer: Voron 2.4 350 | Sources: AliExpress + Mouser (see status column)" -> Tools: 6 | Printer: Voron 2.4 350 | Sources: AliExpress + Mouser (see status column)
A4: Section | B4: Cost (USD)
A5: Printhead | B5: =SUMIF(BOM!$B$5:$B$42,A5,BOM!$J$5:$J$42) -> 68.44
A6: Maxwell coupling & docks | B6: =SUMIF(BOM!$B$5:$B$42,A6,BOM!$J$5:$J$42) -> 31.06
A7: Hotend modules | B7: =SUMIF(BOM!$B$5:$B$42,A7,BOM!$J$5:$J$42) -> 222.34
A8: Electronics & power | B8: =SUMIF(BOM!$B$5:$B$42,A8,BOM!$J$5:$J$42) -> 126.86
A9: Printed parts | B9: =SUMIF(BOM!$B$5:$B$42,A9,BOM!$J$5:$J$42) -> 0
A10: Parts subtotal | B10: =SUM(B5:B9) -> 448.7
A11: Shipping allowance | B11: =Assumptions!B6 -> 15
A12: Sales tax | B12: =B10*Assumptions!B7 -> 43.74825
A13: Import fees allowance | B13: =B10*Assumptions!B8 -> 44.87
A14: Contingency | B14: =(B10+B11)*Assumptions!B9 -> 46.37
A15: ESTIMATED TOTAL | B15: =SUM(B10:B14) -> 598.68825
A16: Budget | B16: =Assumptions!B10 -> 800
A17: Remaining budget | B17: =B16-B15 -> 201.31175
A18: Per-tool cost (hotend modules ÷ tools) | B18: =B7/Assumptions!B4 -> 37.056667
A20: Not included
A21: Spool holders / filament buffers for 6 separate spools.
A22: Klipper config for T4/T5 (upstream ships T0–T3).
A23: Dock mounting bracket design for the Voron frame (DIY. The project gives the head and basic docks only).
A24: Klipper toolchanger plugin (free software).
A25: Spare nozzles.

Sheet Assumptions
A1: CxChanger BOM — Assumptions (edit yellow cells)
A3: Assumption | B3: Value | C3: Note / source
A4: Number of tools (hotend modules) | B4: 6 | C4: Docks = tools. Upstream config ships T0–T3. Add T4/T5 macros + extruder4/5 sections.
A5: Use JLC CNC plates? (Y/N) | B5: N | C5: N = print the plates (printed version exists). Y adds the JLCCNC line.
A6: Est. shipping allowance (USD) | B6: 15 | C6: Assumption: most AliExpress Choice items ship free over ~$10/seller; allowance covers small-seller shipping.
A7: Sales tax rate | B7: 0.0975 | C7: Assumption: Clarksville/Montgomery Co., TN combined rate; AliExpress collects US sales tax at checkout. Verify.
A8: Import fees / duty allowance | B8: 0.1 | C8: Assumption: US de minimis no longer covers China imports; AliExpress usually shows import charges at checkout. Adjust after cart check.
A9: Contingency (wrong parts, re-orders) | B9: 0.1 | C9: Assumption.
A10: Budget (USD) | B10: 800 | C10: From Mike's stated toolchanger budget.
A13: How to use
A14: 1. Change the tool count in B4 — every per-tool quantity on the BOM tab updates.
A15: 2. On the BOM tab, set 'Owned?' to Y for anything you already have; its cost drops to $0.
A16: 3. Replace blue 'Est. price' values with the real cart price as you add each item on AliExpress.
A17: 4. The Summary tab totals everything against your budget.

Sheet BOM
A1: CxChanger BOM (v5.5 BOM + v6.11 changes) — 6 tools, Voron 2.4 350
A2: Checked in a browser on aliexpress.us, 2026-09-30, signed out. Totals use the LIST (strikethrough) price, so they are an upper bound. AliExpress showed $1.09 new-shopper deals on most items; your signed-in cart price will likely be lower. Blue = inputs.
A4: # | B4: Section | C4: Part | D4: Spec | E4: Qty needed | F4: Pack size | G4: Packs to buy | H4: List price / pack (USD) | I4: Owned? (Y/N) | J4: Line cost (USD) | K4: Link | L4: Notes | M4: Verification status (2026-09-30) | N4: Promo price shown (new-shopper, signed out)
A5: 1 | B5: Printhead | C5: HGX gear set (gears only) | D5: Variant: '1 Set HGX Gear' (17/44 double gear + 36T drive gears) | E5: 1 | F5: 1 | G5: =IF(E5=0,0,ROUNDUP(E5/F5,0)) -> 1 | H5: 6.95 | I5: N | J5: =IF(UPPER(I5)="Y",0,G5*H5) -> 6.95 | K5: https://www.aliexpress.us/item/3256808936360634.html | L5: MEGA 3D Printer Store, 800+ sold, free shipping. The old link (3256807033585974) was a full extruder with motor ($21.21, $46 express shipping), so it was replaced. | M5: Browser-verified item + variant | N5: 1.09
A6: 2 | B6: Printhead | C6: Bearing MR63ZZ 3×6×2.5 mm | D6: 10 pcs/lot | E6: 4 | F6: 10 | G6: =IF(E6=0,0,ROUNDUP(E6/F6,0)) -> 1 | H6: 4.01 | I6: N | J6: =IF(UPPER(I6)="Y",0,G6*H6) -> 4.01 | K6: https://www.aliexpress.us/item/3256801934742685.html | L6: Homeclub Store, 1,000+ sold. | M6: Browser-verified item | N6: 1.09
A7: 3 | B7: Printhead | C7: Dowel pin Ø3 × 16 mm | D7: GB119 listing; pick M3 × 16 | E7: 2 | F7: 20 | G7: =IF(E7=0,0,ROUNDUP(E7/F7,0)) -> 1 | H7: 1.9 | I7: N | J7: =IF(UPPER(I7)="Y",0,G7*H7) -> 1.9 | K7: https://www.aliexpress.us/item/3256806837028480.html | L7: 304 stainless (not hardened). Variant price not checked. 5,000+ sold. | M7: Browser-verified listing; variant not priced | N7: 1.09
A8: 4 | B8: Printhead | C8: Dowel pin Ø3 × 24 mm | D8: GB119 listing; pick M3 × 24 | E8: 1 | F8: 20 | G8: =IF(E8=0,0,ROUNDUP(E8/F8,0)) -> 1 | H8: 1.9 | I8: N | J8: =IF(UPPER(I8)="Y",0,G8*H8) -> 1.9 | K8: https://www.aliexpress.us/item/3256806837028480.html | L8: Same listing as above. | M8: Browser-verified listing; variant not priced | N8: 1.09
A9: 5 | B9: Printhead | C9: Compression spring assortment | D9: Small springs for idler | E9: 1 | F9: 1 | G9: =IF(E9=0,0,ROUNDUP(E9/F9,0)) -> 1 | H9: 3 | I9: N | J9: =IF(UPPER(I9)="Y",0,G9*H9) -> 3 | K9: https://www.aliexpress.us/w/wholesale-compression-spring-assortment.html | L9: No listing checked. | M9: Estimate – search link
A10: 6 | B10: Printhead | C10: NEMA14 36 mm pancake stepper (HGX-LITE pinion) | D10: 'for HGX-LITE dual gear, 10 teeth reduction gear' | E10: 1 | F10: 1 | G10: =IF(E10=0,0,ROUNDUP(E10/F10,0)) -> 1 | H10: 8.85 | I10: N | J10: =IF(UPPER(I10)="Y",0,G10*H10) -> 8.85 | K10: https://www.aliexpress.us/item/3256808807952066.html | L10: Pinion must mesh with the HGX 17/44 gear. This listing is sold for HGX-LITE. Alternative: Mellow LDO 36STH20 (item 3256802713546002, $21.37 list / $8.62 shown), but check its pinion. Check your Galileo 2 spare motor first. | M10: Search-page price (item not opened) | N10: 1.09
A11: 7 | B11: Printhead | C11: 2510 axial fan 24 V (hotend/throat) | D11: Variant: 24V, hydraulic bearing | E11: 1 | F11: 1 | G11: =IF(E11=0,0,ROUNDUP(E11/F11,0)) -> 1 | H11: 0.87 | I11: N | J11: =IF(UPPER(I11)="Y",0,G11*H11) -> 0.87 | K11: https://www.aliexpress.us/item/2251832624516972.html | L11: LINK CNC Official Store, 3,000+ sold. | M11: Browser-verified item + variant
A12: 8 | B12: Printhead | C12: 4020 blower fan 24 V | D12: Variant: 4020 24V, XH2.54 plug | E12: 1 | F12: 1 | G12: =IF(E12=0,0,ROUNDUP(E12/F12,0)) -> 1 | H12: 3.27 | I12: N | J12: =IF(UPPER(I12)="Y",0,G12*H12) -> 3.27 | K12: https://www.aliexpress.us/item/2251832787493408.html | L12: IdeaFormer Official Store, 2,000+ sold, free shipping. | M12: Browser-verified item + variant | N12: 1.09
A13: 9 | B13: Printhead | C13: Omron D2F-01F micro switch | D13: Variant: D2F-01F, 1 pc | E13: 2 | F13: 1 | G13: =IF(E13=0,0,ROUNDUP(E13/F13,0)) -> 2 | H13: 0.84 | I13: N | J13: =IF(UPPER(I13)="Y",0,G13*H13) -> 1.68 | K13: https://www.aliexpress.us/item/3256805018062207.html | L13: Qty 2: Z probe + v6.11 tool/filament sensor. Listed 'authentic original'. 5,000+ sold. | M13: Browser-verified item + variant
A14: 10 | B14: Printhead | C14: M4 hex standoffs | D14: Pick M4 × 10 (2) and M4 × 14 (1), female-female | E14: 1 | F14: 1 | G14: =IF(E14=0,0,ROUNDUP(E14/F14,0)) -> 1 | H14: 7.58 | I14: N | J14: =IF(UPPER(I14)="Y",0,G14*H14) -> 7.58 | K14: https://www.aliexpress.us/item/3256808527324482.html | L14: Listing price, variant not checked. | M14: Browser-verified listing; variant not priced | N14: 1.09
A15: 11 | B15: Printhead | C15: M4 hollow (through-hole) socket-head bolt | D15: Pick M4, short length | E15: 1 | F15: 1 | G15: =IF(E15=0,0,ROUNDUP(E15/F15,0)) -> 1 | H15: 1.62 | I15: N | J15: =IF(UPPER(I15)="Y",0,G15*H15) -> 1.62 | K15: https://www.aliexpress.us/item/3256807635919515.html | L15: Original BOM: '带孔螺栓'. | M15: Browser-verified listing; variant not priced | N15: 1.09
A16: 12 | B16: Printhead | C16: Metric screw assortment M2 / M2.5 / M3 | D16: SHCS + nuts | E16: 1 | F16: 1 | G16: =IF(E16=0,0,ROUNDUP(E16/F16,0)) -> 1 | H16: 10 | I16: N | J16: =IF(UPPER(I16)="Y",0,G16*H16) -> 10 | K16: https://www.aliexpress.us/w/wholesale-m2-m2.5-m3-socket-head-screw-kit.html | L16: No listing checked. Set Owned = Y if you have one. | M16: Estimate – search link
A17: 13 | B17: Printhead | C17: M3 × 22 button-head, black 10.9 | D17: Variant: M3 (50pcs), 22mm | E17: 7 | F17: 50 | G17: =IF(E17=0,0,ROUNDUP(E17/F17,0)) -> 1 | H17: 2.44 | I17: N | J17: =IF(UPPER(I17)="Y",0,G17*H17) -> 2.44 | K17: https://www.aliexpress.us/item/2251832782727837.html | L17: HZYUEGOU. | M17: Browser-verified item + variant | N17: 1.09
A18: 14 | B18: Printhead | C18: M3 heat-set inserts | D18: Variant: 100 PCS M3X4X5 | E18: 20 | F18: 100 | G18: =IF(E18=0,0,ROUNDUP(E18/F18,0)) -> 1 | H18: 10.37 | I18: N | J18: =IF(UPPER(I18)="Y",0,G18*H18) -> 10.37 | K18: https://www.aliexpress.us/item/3256810138806595.html | L18: Check the size against the CAD holes (project lists M3 × 4 × 4). | M18: Browser-verified item + variant | N18: 1.09
A19: 15 | B19: Printhead | C19: Self-adhesive high-temp silicone strip 10 × 2 mm | D19: Plugs parked nozzles in the docks | E19: 1 | F19: 1 | G19: =IF(E19=0,0,ROUNDUP(E19/F19,0)) -> 1 | H19: 4 | I19: N | J19: =IF(UPPER(I19)="Y",0,G19*H19) -> 4 | K19: https://www.aliexpress.us/w/wholesale-silicone-strip-10x2mm-adhesive.html | L19: No good AliExpress match found (results were door weather-strip). Consider a silicone sheet instead. | M19: Not found – estimate
A20: 16 | B20: Printhead | C20: JLC CNC plates (5 parts) | D20: Top magnet plate, spring plate, swing arms ×2, back plate | E20: =IF(UPPER(Assumptions!$B$5)="Y",1,0) -> 0 | F20: 1 | G20: =IF(E20=0,0,ROUNDUP(E20/F20,0)) -> 0 | H20: 22 | I20: N | J20: =IF(UPPER(I20)="Y",0,G20*H20) -> 0 | K20: https://jlccnc.com | L20: Not on AliExpress. Controlled by Assumptions B5. | M20: Other vendor – estimate
A21: 17 | B21: Maxwell coupling & docks | C21: Dowel pin Ø1.5 × 5 mm | D21: GB119 listing; pick M1.5 × 5 | E21: 6 | F21: 50 | G21: =IF(E21=0,0,ROUNDUP(E21/F21,0)) -> 1 | H21: 1.9 | I21: N | J21: =IF(UPPER(I21)="Y",0,G21*H21) -> 1.9 | K21: https://www.aliexpress.us/item/3256806837028480.html | L21: Variant price not checked. | M21: Browser-verified listing; variant not priced | N21: 1.09
A22: 18 | B22: Maxwell coupling & docks | C22: Round-head pin Ø3 × 4 mm | D22: 3 per hotend | E22: =3*Assumptions!$B$4 -> 18 | F22: 20 | G22: =IF(E22=0,0,ROUNDUP(E22/F22,0)) -> 1 | H22: 3 | I22: N | J22: =IF(UPPER(I22)="Y",0,G22*H22) -> 3 | K22: https://www.aliexpress.us/w/wholesale-round-head-pin-3mm.html | L22: No match found on AliExpress in 3 searches. Chinese BOM links Tmall item 868817943817. Size 3×4 vs 3×6: check the CAD. | M22: Not found – estimate
A23: 19 | B23: Maxwell coupling & docks | C23: Female-threaded round-head pin M3, Ø5 × 20 mm | D23: 1 per dock | E23: =Assumptions!$B$4 -> 6 | F23: 10 | G23: =IF(E23=0,0,ROUNDUP(E23/F23,0)) -> 1 | H23: 4 | I23: N | J23: =IF(UPPER(I23)="Y",0,G23*H23) -> 4 | K23: https://www.aliexpress.us/w/wholesale-m3-internal-thread-round-head-pin-5mm.html | L23: No match found on AliExpress. Chinese BOM links Tmall item 864132087543. | M23: Not found – estimate
A24: 20 | B24: Maxwell coupling & docks | C24: N52 magnet Ø6 × 4 mm | D24: Variant: 6x4mm N52, 50pcs | E24: =4*Assumptions!$B$4+3 -> 27 | F24: 50 | G24: =IF(E24=0,0,ROUNDUP(E24/F24,0)) -> 1 | H24: 12.94 | I24: N | J24: =IF(UPPER(I24)="Y",0,G24*H24) -> 12.94 | K24: https://www.aliexpress.us/item/3256809533301082.html | L24: Magnet Customised Factory Store, 1,000+ sold. 30pcs is $9.65 and 100pcs is $18.49. | M24: Browser-verified item + variant | N24: 1.09
A25: 21 | B25: Maxwell coupling & docks | C25: M3 black grade 12.9 socket-head screw (hook) | D25: DIN912; length per CAD | E25: =Assumptions!$B$4 -> 6 | F25: 50 | G25: =IF(E25=0,0,ROUNDUP(E25/F25,0)) -> 1 | H25: 1.5 | I25: N | J25: =IF(UPPER(I25)="Y",0,G25*H25) -> 1.5 | K25: https://www.aliexpress.us/item/3256805693063078.html | L25: Listing shows ~$0.02/pc. Must be 12.9 alloy steel so the magnets hold it. | M25: Search-page price (item not opened) | N25: 1.09
A26: 22 | B26: Maxwell coupling & docks | C26: Dock cooling fan 2510 24 V, 1 per dock | D26: Same LINK CNC listing, 24V | E26: =Assumptions!$B$4 -> 6 | F26: 1 | G26: =IF(E26=0,0,ROUNDUP(E26/F26,0)) -> 6 | H26: 0.87 | I26: N | J26: =IF(UPPER(I26)="Y",0,G26*H26) -> 5.22 | K26: https://www.aliexpress.us/item/2251832624516972.html | L26: Size assumed; verify in the 6.11 dock STEP. | M26: Browser-verified item + variant
A27: 23 | B27: Maxwell coupling & docks | C27: M3 roll-in spring T-nuts (2020) | D27: 2 per dock; 50 pcs | E27: =2*Assumptions!$B$4 -> 12 | F27: 50 | G27: =IF(E27=0,0,ROUNDUP(E27/F27,0)) -> 1 | H27: 2.5 | I27: N | J27: =IF(UPPER(I27)="Y",0,G27*H27) -> 2.5 | K27: https://www.aliexpress.us/item/2251832837457300.html | L27: Listing shows ~$0.05/pc. | M27: Search-page price (item not opened) | N27: 1.09
A28: 24 | B28: Hotend modules | C28: TZ 2.0 hotend (Bambu X1/P1 style) – Mellow | D28: Variant: 'TZ2 Hotend' | E28: =Assumptions!$B$4 -> 6 | F28: 1 | G28: =IF(E28=0,0,ROUNDUP(E28/F28,0)) -> 6 | H28: 19.98 | I28: N | J28: =IF(UPPER(I28)="Y",0,G28*H28) -> 119.88 | K28: https://www.aliexpress.us/item/3256805875155396.html | L28: Mellow 3D Official Store (only 28 sold). The Trianglelab link from the last BOM (1005005920817062) now returns 'page not found' on aliexpress.us. Alternative: YUNSN TZ2.0 kit with 60W heater, item 3256808914626535, 'Hotend for X1' $42.15 list / $33.72 sale. Check whether the Mellow hotend includes a heater. | M28: Browser-verified item + variant | N28: 1.09
A29: 25 | B29: Hotend modules | C29: Ceramic heater 24 V 48 W + NTC 100K 3950 | D29: Pick 48W (not 60W/82W) | E29: =Assumptions!$B$4 -> 6 | F29: 1 | G29: =IF(E29=0,0,ROUNDUP(E29/F29,0)) -> 6 | H29: 3.4 | I29: N | J29: =IF(UPPER(I29)="Y",0,G29*H29) -> 20.4 | K29: https://www.aliexpress.us/item/3256808485891466.html | L29: Use 48 W: 6 × 82 W = 492 W would overload the 350 W PSU during simultaneous preheat. Set sensor_type to Generic 3950. Upstream uses ATC Semitec 104GT-2. | M29: Search-page price (item not opened) | N29: 2.72
A30: 26 | B30: Hotend modules | C30: Silicone sock, Bambu X1/P1 | D30: Variant: For BambuLab X1 P1, 1pcs | E30: =Assumptions!$B$4 -> 6 | F30: 1 | G30: =IF(E30=0,0,ROUNDUP(E30/F30,0)) -> 6 | H30: 1.79 | I30: N | J30: =IF(UPPER(I30)="Y",0,G30*H30) -> 10.74 | K30: https://www.aliexpress.us/item/3256808316755061.html | L30: Multi-packs (3/5/10) are available; buying 10 is likely cheaper. | M30: Browser-verified item + variant | N30: 1.09
A31: 27 | B31: Hotend modules | C31: Flexible towline cable 4-core 22 AWG | D31: Heater + thermistor, per metre | E31: =1.5*Assumptions!$B$4 -> 9 | F31: 1 | G31: =IF(E31=0,0,ROUNDUP(E31/F31,0)) -> 9 | H31: 3.03 | I31: N | J31: =IF(UPPER(I31)="Y",0,G31*H31) -> 27.27 | K31: https://www.aliexpress.us/item/2255800968230040.html | L31: Qty in metres. Pick 4-core 22 AWG. Price shown for the default variant. | M31: Search-page price (item not opened) | N31: 2.33
A32: 28 | B32: Hotend modules | C32: Molex Micro-Fit 3.0 housings + terminals | D32: 10 sets, 2-pin | E32: =2*Assumptions!$B$4 -> 12 | F32: 10 | G32: =IF(E32=0,0,ROUNDUP(E32/F32,0)) -> 2 | H32: 2.03 | I32: N | J32: =IF(UPPER(I32)="Y",0,G32*H32) -> 4.06 | K32: https://www.aliexpress.us/item/3256802961371687.html | L32: 2 connectors per tool (heater + thermistor). | M32: Search-page price (item not opened) | N32: 1.93
A33: 29 | B33: Hotend modules | C33: Capricorn PTFE 1 m (head liner) | D33: Variant: 1M PTFE | E33: 1 | F33: 1 | G33: =IF(E33=0,0,ROUNDUP(E33/F33,0)) -> 1 | H33: 7.69 | I33: N | J33: =IF(UPPER(I33)="Y",0,G33*H33) -> 7.69 | K33: https://www.aliexpress.us/item/3256804674205585.html | L33: Creality Capricorn. Only the head path needs Capricorn. | M33: Browser-verified item + variant | N33: 1.09
A34: 30 | B34: Hotend modules | C34: Generic PTFE 2 × 4 mm (tool feed tubes) | D34: ~1.5 m per tool | E34: =1.5*Assumptions!$B$4 -> 9 | F34: 5 | G34: =IF(E34=0,0,ROUNDUP(E34/F34,0)) -> 2 | H34: 6 | I34: N | J34: =IF(UPPER(I34)="Y",0,G34*H34) -> 12 | K34: https://www.aliexpress.us/w/wholesale-ptfe-tube-2x4mm-5m.html | L34: Qty in metres. No listing checked. | M34: Estimate – search link
A35: 31 | B35: Hotend modules | C35: PC4-M6 push fittings | D35: Variant: PC4-M6-10pcs | E35: =2*Assumptions!$B$4 -> 12 | F35: 10 | G35: =IF(E35=0,0,ROUNDUP(E35/F35,0)) -> 2 | H35: 10.15 | I35: N | J35: =IF(UPPER(I35)="Y",0,G35*H35) -> 20.3 | K35: https://www.aliexpress.us/item/3256809971210588.html | M35: Browser-verified item + variant | N35: 1.09
A36: 32 | B36: Electronics & power | C36: Mainboard heater/thermistor ports (T0–T3) | D36: BTT Manta M8P: HE0–HE3 + TH0–TH3 | E36: 1 | F36: 1 | G36: =IF(E36=0,0,ROUNDUP(E36/F36,0)) -> 1 | H36: 0 | I36: Y | J36: =IF(UPPER(I36)="Y",0,G36*H36) -> 0 | L36: Owned. Covers 4 of 6 tools. | M36: —
A37: 33 | B37: Electronics & power | C37: BTT EBB36 CAN V1.2 (T4–T5) | D37: Variant: 'EBB 36' (no MAX31865) | E37: =MAX(0,Assumptions!$B$4-4) -> 2 | F37: 1 | G37: =IF(E37=0,0,ROUNDUP(E37/F37,0)) -> 2 | H37: 36.37 | I37: N | J37: =IF(UPPER(I37)="Y",0,G37*H37) -> 72.74 | K37: https://www.aliexpress.us/item/3256807670809484.html | L37: AliExpress list $36.37 (vs $19.99 at biqu.equipment). Your 2 spare EBB SB2209s do the same job: set Owned = Y. | M37: Browser-verified item + variant | N37: 4.41
A38: 34 | B38: Electronics & power | C38: CAN cable (twisted pair + 24 V) | D38: ~2 m | E38: =IF(Assumptions!$B$4>4,1,0) -> 1 | F38: 1 | G38: =IF(E38=0,0,ROUNDUP(E38/F38,0)) -> 1 | H38: 6 | I38: N | J38: =IF(UPPER(I38)="Y",0,G38*H38) -> 6 | K38: https://www.aliexpress.us/w/wholesale-can-bus-cable-4-core-twisted.html | L38: No good AliExpress match found. | M38: Not found – estimate
A39: 35 | B39: Electronics & power | C39: Mean Well LRS-350-24 (24 V 14.6 A, 350 W) | D39: Dedicated hotend PSU | E39: 1 | F39: 1 | G39: =IF(E39=0,0,ROUNDUP(E39/F39,0)) -> 1 | H39: 32.1 | I39: N | J39: =IF(UPPER(I39)="Y",0,G39*H39) -> 32.1 | K39: https://www.mouser.com/ProductDetail/MEAN-WELL/LRS-350-24?qs=ah3jBNVE1PT%2BkwLcackrGA%3D%3D | L39: Mouser $32.10 (TRC $34.81). From an authorized distributor, not AliExpress. | M39: Authorized distributor – price verified
A40: 36 | B40: Electronics & power | C40: Ferrule crimper + ferrule kit | D40: For PSU AC/DC wiring | E40: 1 | F40: 1 | G40: =IF(E40=0,0,ROUNDUP(E40/F40,0)) -> 1 | H40: 16.02 | I40: N | J40: =IF(UPPER(I40)="Y",0,G40*H40) -> 16.02 | K40: https://www.aliexpress.us/item/3256809851025256.html | L40: Skip if you have a crimper. Common DC − between the PSUs; earth both chassis. | M40: Search-page price (item not opened) | N40: 1.09
A41: 37 | B41: Electronics & power | C41: Nozzle offset calibration probe | D41: BTT Eddy (owned) or ball probe | E41: 1 | F41: 1 | G41: =IF(E41=0,0,ROUNDUP(E41/F41,0)) -> 1 | H41: 0 | I41: Y | J41: =IF(UPPER(I41)="Y",0,G41*H41) -> 0 | L41: Owned. | M41: —
...

Sheet Sources
A1: Sources
A3: CxChanger original repo + 5.5 BOM (quantities, ¥ prices) | B3: https://github.com/cx330-TXY/CxChanger
A4: CxChanger English translation (parts list, pin sizes) | B4: https://github.com/WheelsTheCat/CxChanger
A5: Trianglelab TZ-V6-2.0 hotend list price ($27) | B5: https://www.trianglelab.net/products/tz-v6-20-hotend
A6: AliExpress TZ 2.0 hotend listing | B6: https://www.aliexpress.com/item/1005005920817062.html
A7: AliExpress ceramic heater + thermistor listing | B7: https://www.aliexpress.us/item/3256807569217043.html
A8: AliExpress 36 mm pancake stepper listing | B8: https://www.aliexpress.us/item/3256804107613674.html
A9: AliExpress HGX gear set listing | B9: https://www.aliexpress.us/item/3256807033585974.html
A10: Mouser LRS-350-24 ($32.10, verified 2026-09-30) | B10: https://www.mouser.com/ProductDetail/MEAN-WELL/LRS-350-24?qs=ah3jBNVE1PT%2BkwLcackrGA%3D%3D
A11: TRC Electronics LRS-350-24 ($34.81) | B11: https://www.trcelectronics.com/products/mean-well-lrs-350-24
A12: Trianglelab TZ 2.0 for Bambu ($45.99) | B12: https://trianglelab.net/products/tz-20-hotend-for-bambu-lab-x1-p1p
A13: BIQU EBB36/42 (from $19.99) | B13: https://biqu.equipment/products/bigtreetech-ebb36-42-can-bus-u2c-v2-1-klipper-board
A14: AliExpress EBB36 CAN V1.2 listing | B14: https://www.aliexpress.us/item/3256804056891440.html
A15: Upstream v6.11 changes (2026-09-29): new printhead 6.11 zip, dock 6.11 STEP, tool-change-failure + runout sensor | B15: https://github.com/cx330-TXY/CxChanger/commits/main
A16: Note: AliExpress blocks automated reads. AliExpress prices are estimates; verify in cart.
